2019-02-23 12:45:30,755 ERROR: Exception on /user/rak [GET] [in /Users/tberg/Documents/Dev/PyCharm/microblog/venv/lib/python3.7/site-packages/flask/app.py:1761]
Traceback (most recent call last):
  File "/Users/tberg/Documents/Dev/PyCharm/microblog/venv/lib/python3.7/site-packages/flask/app.py", line 2292, in wsgi_app
    response = self.full_dispatch_request()
  File "/Users/tberg/Documents/Dev/PyCharm/microblog/venv/lib/python3.7/site-packages/flask/app.py", line 1815, in full_dispatch_request
    rv = self.handle_user_exception(e)
  File "/Users/tberg/Documents/Dev/PyCharm/microblog/venv/lib/python3.7/site-packages/flask/app.py", line 1718, in handle_user_exception
    reraise(exc_type, exc_value, tb)
  File "/Users/tberg/Documents/Dev/PyCharm/microblog/venv/lib/python3.7/site-packages/flask/_compat.py", line 35, in reraise
    raise value
  File "/Users/tberg/Documents/Dev/PyCharm/microblog/venv/lib/python3.7/site-packages/flask/app.py", line 1813, in full_dispatch_request
    rv = self.dispatch_request()
  File "/Users/tberg/Documents/Dev/PyCharm/microblog/venv/lib/python3.7/site-packages/flask/app.py", line 1799, in dispatch_request
    return self.view_functions[rule.endpoint](**req.view_args)
  File "/Users/tberg/Documents/Dev/PyCharm/microblog/venv/lib/python3.7/site-packages/flask_login/utils.py", line 261, in decorated_view
    return func(*args, **kwargs)
  File "/Users/tberg/Documents/Dev/PyCharm/microblog/app/routes.py", line 110, in user
    next_url = url_for('user/<username>', page=posts.next_num) if posts.has_next else None
  File "/Users/tberg/Documents/Dev/PyCharm/microblog/venv/lib/python3.7/site-packages/flask/helpers.py", line 356, in url_for
    return appctx.app.handle_url_build_error(error, endpoint, values)
  File "/Users/tberg/Documents/Dev/PyCharm/microblog/venv/lib/python3.7/site-packages/flask/app.py", line 2061, in handle_url_build_error
    reraise(exc_type, exc_value, tb)
  File "/Users/tberg/Documents/Dev/PyCharm/microblog/venv/lib/python3.7/site-packages/flask/_compat.py", line 35, in reraise
    raise value
  File "/Users/tberg/Documents/Dev/PyCharm/microblog/venv/lib/python3.7/site-packages/flask/helpers.py", line 345, in url_for
    force_external=external)
  File "/Users/tberg/Documents/Dev/PyCharm/microblog/venv/lib/python3.7/site-packages/werkzeug/routing.py", line 1776, in build
    raise BuildError(endpoint, values, method, self)
werkzeug.routing.BuildError: Could not build url for endpoint 'user/<username>' with values ['page']. Did you mean 'user' instead?
2019-02-23 12:46:14,074 INFO: Microblog startup [in /Users/tberg/Documents/Dev/PyCharm/microblog/app/__init__.py:49]
2019-02-23 12:46:14,717 ERROR: Exception on /user/rak [GET] [in /Users/tberg/Documents/Dev/PyCharm/microblog/venv/lib/python3.7/site-packages/flask/app.py:1761]
Traceback (most recent call last):
  File "/Users/tberg/Documents/Dev/PyCharm/microblog/venv/lib/python3.7/site-packages/flask/app.py", line 2292, in wsgi_app
    response = self.full_dispatch_request()
  File "/Users/tberg/Documents/Dev/PyCharm/microblog/venv/lib/python3.7/site-packages/flask/app.py", line 1815, in full_dispatch_request
    rv = self.handle_user_exception(e)
  File "/Users/tberg/Documents/Dev/PyCharm/microblog/venv/lib/python3.7/site-packages/flask/app.py", line 1718, in handle_user_exception
    reraise(exc_type, exc_value, tb)
  File "/Users/tberg/Documents/Dev/PyCharm/microblog/venv/lib/python3.7/site-packages/flask/_compat.py", line 35, in reraise
    raise value
  File "/Users/tberg/Documents/Dev/PyCharm/microblog/venv/lib/python3.7/site-packages/flask/app.py", line 1813, in full_dispatch_request
    rv = self.dispatch_request()
  File "/Users/tberg/Documents/Dev/PyCharm/microblog/venv/lib/python3.7/site-packages/flask/app.py", line 1799, in dispatch_request
    return self.view_functions[rule.endpoint](**req.view_args)
  File "/Users/tberg/Documents/Dev/PyCharm/microblog/venv/lib/python3.7/site-packages/flask_login/utils.py", line 261, in decorated_view
    return func(*args, **kwargs)
  File "/Users/tberg/Documents/Dev/PyCharm/microblog/app/routes.py", line 111, in user
    next_url = url_for('user/<username>', page=posts.next_num) if posts.has_next else None
  File "/Users/tberg/Documents/Dev/PyCharm/microblog/venv/lib/python3.7/site-packages/flask/helpers.py", line 356, in url_for
    return appctx.app.handle_url_build_error(error, endpoint, values)
  File "/Users/tberg/Documents/Dev/PyCharm/microblog/venv/lib/python3.7/site-packages/flask/app.py", line 2061, in handle_url_build_error
    reraise(exc_type, exc_value, tb)
  File "/Users/tberg/Documents/Dev/PyCharm/microblog/venv/lib/python3.7/site-packages/flask/_compat.py", line 35, in reraise
    raise value
  File "/Users/tberg/Documents/Dev/PyCharm/microblog/venv/lib/python3.7/site-packages/flask/helpers.py", line 345, in url_for
    force_external=external)
  File "/Users/tberg/Documents/Dev/PyCharm/microblog/venv/lib/python3.7/site-packages/werkzeug/routing.py", line 1776, in build
    raise BuildError(endpoint, values, method, self)
werkzeug.routing.BuildError: Could not build url for endpoint 'user/<username>' with values ['page']. Did you mean 'user' instead?
2019-02-23 12:46:41,755 INFO: Microblog startup [in /Users/tberg/Documents/Dev/PyCharm/microblog/app/__init__.py:49]
2019-02-23 12:46:42,717 ERROR: Exception on /user/rak [GET] [in /Users/tberg/Documents/Dev/PyCharm/microblog/venv/lib/python3.7/site-packages/flask/app.py:1761]
Traceback (most recent call last):
  File "/Users/tberg/Documents/Dev/PyCharm/microblog/venv/lib/python3.7/site-packages/flask/app.py", line 2292, in wsgi_app
    response = self.full_dispatch_request()
  File "/Users/tberg/Documents/Dev/PyCharm/microblog/venv/lib/python3.7/site-packages/flask/app.py", line 1815, in full_dispatch_request
    rv = self.handle_user_exception(e)
  File "/Users/tberg/Documents/Dev/PyCharm/microblog/venv/lib/python3.7/site-packages/flask/app.py", line 1718, in handle_user_exception
    reraise(exc_type, exc_value, tb)
  File "/Users/tberg/Documents/Dev/PyCharm/microblog/venv/lib/python3.7/site-packages/flask/_compat.py", line 35, in reraise
    raise value
  File "/Users/tberg/Documents/Dev/PyCharm/microblog/venv/lib/python3.7/site-packages/flask/app.py", line 1813, in full_dispatch_request
    rv = self.dispatch_request()
  File "/Users/tberg/Documents/Dev/PyCharm/microblog/venv/lib/python3.7/site-packages/flask/app.py", line 1799, in dispatch_request
    return self.view_functions[rule.endpoint](**req.view_args)
  File "/Users/tberg/Documents/Dev/PyCharm/microblog/venv/lib/python3.7/site-packages/flask_login/utils.py", line 261, in decorated_view
    return func(*args, **kwargs)
  File "/Users/tberg/Documents/Dev/PyCharm/microblog/app/routes.py", line 111, in user
    next_url = url_for('user', page=posts.next_num) if posts.has_next else None
  File "/Users/tberg/Documents/Dev/PyCharm/microblog/venv/lib/python3.7/site-packages/flask/helpers.py", line 356, in url_for
    return appctx.app.handle_url_build_error(error, endpoint, values)
  File "/Users/tberg/Documents/Dev/PyCharm/microblog/venv/lib/python3.7/site-packages/flask/app.py", line 2061, in handle_url_build_error
    reraise(exc_type, exc_value, tb)
  File "/Users/tberg/Documents/Dev/PyCharm/microblog/venv/lib/python3.7/site-packages/flask/_compat.py", line 35, in reraise
    raise value
  File "/Users/tberg/Documents/Dev/PyCharm/microblog/venv/lib/python3.7/site-packages/flask/helpers.py", line 345, in url_for
    force_external=external)
  File "/Users/tberg/Documents/Dev/PyCharm/microblog/venv/lib/python3.7/site-packages/werkzeug/routing.py", line 1776, in build
    raise BuildError(endpoint, values, method, self)
werkzeug.routing.BuildError: Could not build url for endpoint 'user' with values ['page']. Did you forget to specify values ['username']?
2019-02-23 12:48:51,065 INFO: Microblog startup [in /Users/tberg/Documents/Dev/PyCharm/microblog/app/__init__.py:49]
2019-02-23 12:49:00,360 INFO: Microblog startup [in /Users/tberg/Documents/Dev/PyCharm/microblog/app/__init__.py:49]
2019-02-23 13:17:05,489 INFO: Microblog startup [in /Users/tberg/Documents/Dev/PyCharm/microblog/app/__init__.py:49]
2019-02-23 13:17:08,616 INFO: Microblog startup [in /Users/tberg/Documents/Dev/PyCharm/microblog/app/__init__.py:49]
